Workbook
Name FUNC_PASS: LAMBDA(IF(AND(#REF!<>"",#REF!<> ""), IF(#REF!="", "P",#REF!), ""))
Name FUNC_PASS: LAMBDA(IF(AND(#REF!<>"",#REF!<> ""), IF(#REF!="", "P",#REF!), ""))
Name FUNC_PASS: LAMBDA(IF(AND(#REF!<>"",#REF!<> ""), IF(#REF!="", "P",#REF!), ""))

Sheet Trang bìa
D1: CÔNG TY CỔ PHẦN GIẢI PHÁP CÔNG NGHỆ
A10: TÀI LIỆU KỊCH BẢN KIỂM THỬ CHỨC NĂNG
C16: Mã dự án | D16: :HRM- Tuyển dụng
C17: Mã tài liệu | D17: KBKTCN
A20: Người lập: | B20: HÒA THỊ THU AN
F21: Ngày lập: 21/7/2026
A26: Người kiểm tra: | C26: ….lead/người review
F27: Ngày kiểm tra:
A32: Người phê duyệt:
F33: Ngày phê duyệt:
A37: BẢNG GHI NHẬN THAY ĐỔI TÀI LIỆU
A39: Ngày thay đổi | B39: Vị trí thay đổi | C39: Lý do | D39: Nguồn gốc | E39: Phiên bản cũ | F39: Mô tả thay đổi | G39: Phiên bản mới
A40: 46224 | B40: Toàn bộ | C40: Thêm mới | F40: Thêm mới bộ test case | G40: v1.0

Sheet Tổng hợp
A2: TỔNG HỢP KẾT QUẢ
A4: STT | B4: Tên màn hình/chức năng | C4: Số trường hợp kiểm thử đạt (P) | D4: Số trường hợp kiểm thử không đạt (F) | E4: Số trường hợp kiểm thử đang xem xét (PE) | F4: Số trường hợp kiểm thử chưa thực hiện | G4: Tổng số trường hợp kiểm thử | H4: Tỉ lệ trường hợp kiểm thử đạt (%P) | I4: Tỉ lệ trường hợp kiểm thử không đạt (%F) | J4: Tỉ lệ trường hợp kiểm thử đã thực hiện (%Cover)
A5: 1 | B5: =API_dang_nhap_extension!D2 -> API đăng nhập extension | C5: =API_dang_nhap_extension!D4 -> 0 | D5: =API_dang_nhap_extension!D5 -> 0 | E5: =API_dang_nhap_extension!D6 -> 0 | F5: =API_dang_nhap_extension!D7 -> 27 | G5: =API_dang_nhap_extension!D8 -> 27 | H5: =C5/G5*100% -> 0 | I5: =D5/G5*100% -> 0 | J5: =(C5+D5)/G5*100% -> 0
A6: 2 | B6: =API_lay_thong_tin_user!D2 -> API lấy thông tin user | C6: =API_dang_nhap_extension!D4 -> 0 | D6: =API_lay_thong_tin_user!D5 -> 0 | E6: =API_lay_thong_tin_user!D6 -> 0 | F6: =API_lay_thong_tin_user!D7 -> 11 | G6: =API_lay_thong_tin_user!D8 -> 11 | H6: =C6/G6*100% -> 0 | I6: =D6/G6*100% -> 0 | J6: =(C6+D6)/G6*100% -> 0
A7: 3 | B7: =API_lam_moi_phien_đn!D2 -> API làm mới phiên đăng nhập | C7: =API_lam_moi_phien_đn!D4 -> 0 | D7: =API_lam_moi_phien_đn!D5 -> 0 | E7: =API_lam_moi_phien_đn!D6 -> 0 | F7: =API_lam_moi_phien_đn!D7 -> 17 | G7: =API_lam_moi_phien_đn!D8 -> 17 | H7: =C7/G7*100% -> 0 | I7: =D7/G7*100% -> 0 | J7: =(C7+D7)/G7*100% -> 0
A8: 4 | B8: =#REF! -> #REF! | C8: =#REF! -> #REF! | D8: =#REF! -> #REF! | E8: =#REF! -> #REF! | F8: =#REF! -> #REF! | G8: =#REF! -> #REF! | H8: =C8/G8*100% -> #REF! | I8: =D8/G8*100% -> #REF! | J8: =(C8+D8)/G8*100% -> #REF!
A9: Total | C9: =SUM(C5:C8) -> #REF! | D9: =SUM(D5:D8) -> #REF! | E9: =SUM(E5:E8) -> #REF! | F9: =SUM(F5:F8) -> #REF! | G9: =SUM(G5:G8) -> #REF! | H9: =C9/G9*100% -> #REF! | I9: =D9/G9*100% -> #REF! | J9: =(C9+D9)/G9*100% -> #REF!

Sheet API_dang_nhap_extension
C1: KỊCH BẢN KIỂM THỬ *
C2: Tên màn hình/Tên chức năng | D2: API đăng nhập extension
C3: Mã testcase | D3: AU1
C4: Số testcase đạt (P) | D4: =COUNTIF($N$13:$N$186,"P") -> 0
C5: Số testcase không đạt (F) | D5: =COUNTIF($N$13:$N$186,"F") -> 0
C6: Số testcase đang xem xét (PE) | D6: =COUNTIF($N$13:$N$186,"PE") -> 0
C7: Số testcase chưa test | D7: =D8-D4-D5-D6 -> 27
C8: Tổng số testcase | D8: =COUNTA($G$13:$G$186) -> 27
A10: ID | B10: Mục đích kiểm thử | C10: Trường hợp kiểm thử | D10: Data test | E10: cURL | F10: Các bước thực hiện | G10: Kết quả mong muốn | H10: Thứ tự ưu tiên | I10: Mức độ nghiêm trọng | J10: Hình ảnh | K10: Manual test | N10: Kết quả test (M) | O10: Mã lỗi | P10: Ghi chú
K11: Postman
K12: Lần 1 | L12: Lần 2 | M12: Lần 3
B13: Chức năng: Đăng nhập extension Method: POST MT alpha: Url: http://192.168.1.131:3002/api/auth/login body { "email": "hr@example.com", "password": "Test@123456" }
A14: =IF(AND(G14="",G14=""),"",$D$3&"_"&ROW()-13-COUNTBLANK($G$14:G14)) | B14: Giao diện (Phần này viết các trường hợp kiểm thử cho giao diên chung và các giao diện cho các control)
A15: =IF(AND(G15="",G15=""),"",$D$3&"_"&ROW()-13-COUNTBLANK($G$14:G15)) | B15: Kiểm tra truyền vào URL
A16: =IF(AND(G16="",G16=""),"",$D$3&"_"&ROW()-13-COUNTBLANK($G$14:G16)) -> AU1_1 | B16: Kiểm tra path | C16: Sai đường dẫn | D16: http://192.168.1.131:3002/api/auth/login12 | F16: 1. Truyền sai path 2. Các trường required, method có dữ liệu hợp lệ | G16: 1. Kết quả trả về: status 404 | H16: MEDIUM | I16: MAJOR | N16: =IF(OR(IF(M16="",IF(L16="",IF(K16="","",K16), L16),M16)="F")=TRUE,"F", IF(OR( IF(M16="",IF(L16="",IF(K16="","",K16), L16),M16)="PE")=TRUE,"PE", IF(AND(IF(M16="",IF(L16="",IF(K16="","",K16), L16),M16)="")=TRUE,"","P")))
A17: =IF(AND(G17="",G17=""),"",$D$3&"_"&ROW()-13-COUNTBLANK($G$14:G17)) -> AU1_2 | C17: Không nhập đường dẫn | D17: Enter URL or text = null | F17: 1. Không truyền path 2. Các trường required, method có dữ liệu hợp lệ | G17: 1. Kết quả trả về: status 404 | H17: MEDIUM | I17: MAJOR | N17: =IF(OR(IF(M17="",IF(L17="",IF(K17="","",K17), L17),M17)="F")=TRUE,"F", IF(OR( IF(M17="",IF(L17="",IF(K17="","",K17), L17),M17)="PE")=TRUE,"PE", IF(AND(IF(M17="",IF(L17="",IF(K17="","",K17), L17),M17)="")=TRUE,"","P")))
A18: =IF(AND(G18="",G18=""),"",$D$3&"_"&ROW()-13-COUNTBLANK($G$14:G18)) -> AU1_3 | C18: Đường dẫn đúng | D18: { "email": "hr@example.com", "password": "Test@123456" } | F18: 1. Truyền path đúng 2. Các trường required, method có dữ liệu hợp lệ | G18: 1. Kết quả trả về: { "accessToken": "jwt...", "refreshToken": "refresh...", "user": { "id": "user-id", "email": "hr.test@example.com", "role": "HR", } } | H18: HIGH | I18: MAJOR | N18: =IF(OR(IF(M18="",IF(L18="",IF(K18="","",K18), L18),M18)="F")=TRUE,"F", IF(OR( IF(M18="",IF(L18="",IF(K18="","",K18), L18),M18)="PE")=TRUE,"PE", IF(AND(IF(M18="",IF(L18="",IF(K18="","",K18), L18),M18)="")=TRUE,"","P")))
A19: =IF(AND(G19="",G19=""),"",$D$3&"_"&ROW()-13-COUNTBLANK($G$14:G19)) -> AU1_4 | B19: Kiểm tra method | C19: Kiểm tra truyền đúng method | D19: Method: POST { "email": "hr@example.com", "password": "Test@123456" } | F19: 1. Truyền path đúng 2. Truyền method đúng 3. Các trường required có dữ liệu hợp lệ | G19: 1. Kết quả trả về: { "accessToken": "jwt...", "refreshToken": "refresh...", "user": { "id": "user-id", "email": "hr.test@example.com", "role": "HR", } } | H19: HIGH | I19: MAJOR
A20: =IF(AND(G20="",G20=""),"",$D$3&"_"&ROW()-13-COUNTBLANK($G$14:G20)) -> AU1_5 | C20: Kiểm tra truyền sai method | D20: Method: GET { "email": "hr@example.com", "password": "Test@123456" } | F20: 1. Truyền path đúng 2. Truyền method sai 3. Các trường required có dữ liệu hợp lệ | G20: 1. Kết quả trả về: status 404 | H20: MEDIUM | I20: MAJOR
A21: =IF(AND(G21="",G21=""),"",$D$3&"_"&ROW()-13-COUNTBLANK($G$14:G21)) | B21: Kiểm tra validate các trường thông tin
A22: =IF(AND(G22="",G22=""),"",$D$3&"_"&ROW()-13-COUNTBLANK($G$14:G22)) | B22: Kiểm tra trường email
A23: =IF(AND(G23="",G23=""),"",$D$3&"_"&ROW()-13-COUNTBLANK($G$14:G23)) -> AU1_6 | B23: Kiểm tra trường email | C23: Kiểm tra không truyền email | D23: { "password": "Test@123456" } | F23: 1. Ko truyền email 2. Các trường required có dữ liệu hợp lệ 3. Nhấn send | G23: Hiển thị lỗi 401 Unauthorized - Authentication is required | H23: MEDIUM | I23: MAJOR | N23: =IF(OR(IF(M23="",IF(L23="",IF(K23="","",K23), L23),M23)="F")=TRUE,"F", IF(OR( IF(M23="",IF(L23="",IF(K23="","",K23), L23),M23)="PE")=TRUE,"PE", IF(AND(IF(M23="",IF(L23="",IF(K23="","",K23), L23),M23)="")=TRUE,"","P")))
A24: =IF(AND(G24="",G24=""),"",$D$3&"_"&ROW()-13-COUNTBLANK($G$14:G24)) -> AU1_7 | C24: Kiểm tra truyền email = null | D24: { "email": null, "password": "Test@123456" } | F24: 1. email = data test 2. Các trường required có dữ liệu hợp lệ 3. Nhấn send | G24: Hiển thị lỗi 401 Unauthorized - Authentication is required | H24: MEDIUM | I24: MAJOR | N24: =IF(OR(IF(M24="",IF(L24="",IF(K24="","",K24), L24),M24)="F")=TRUE,"F", IF(OR( IF(M24="",IF(L24="",IF(K24="","",K24), L24),M24)="PE")=TRUE,"PE", IF(AND(IF(M24="",IF(L24="",IF(K24="","",K24), L24),M24)="")=TRUE,"","P")))
A25: =IF(AND(G25="",G25=""),"",$D$3&"_"&ROW()-13-COUNTBLANK($G$14:G25)) -> AU1_8 | C25: Kiểm tra truyền email = rỗng | D25: { "email": "", "password": "Test@123456" } | F25: 1. email = data test 2. Các trường required có dữ liệu hợp lệ 3. Nhấn send | G25: Hiển thị lỗi 401 Unauthorized - Authentication is required | H25: MEDIUM | I25: MAJOR | N25: =IF(OR(IF(M25="",IF(L25="",IF(K25="","",K25), L25),M25)="F")=TRUE,"F", IF(OR( IF(M25="",IF(L25="",IF(K25="","",K25), L25),M25)="PE")=TRUE,"PE", IF(AND(IF(M25="",IF(L25="",IF(K25="","",K25), L25),M25)="")=TRUE,"","P")))
A26: =IF(AND(G26="",G26=""),"",$D$3&"_"&ROW()-13-COUNTBLANK($G$14:G26)) -> AU1_9 | C26: Kiểm tra truyền email = chuỗi space | D26: { "email": " ", "password": "Test@123456" } | F26: 1. email = data test 2. Các trường required có dữ liệu hợp lệ 3. Nhấn send | G26: Hiển thị lỗi 401 Unauthorized - Authentication is required | H26: MEDIUM | I26: MAJOR | N26: =IF(OR(IF(M26="",IF(L26="",IF(K26="","",K26), L26),M26)="F")=TRUE,"F", IF(OR( IF(M26="",IF(L26="",IF(K26="","",K26), L26),M26)="PE")=TRUE,"PE", IF(AND(IF(M26="",IF(L26="",IF(K26="","",K26), L26),M26)="")=TRUE,"","P")))
A27: =IF(AND(G27="",G27=""),"",$D$3&"_"&ROW()-13-COUNTBLANK($G$14:G27)) -> AU1_10 | C27: Kiểm tra truyền email tồn tại trong DB | D27: { "email": "hr@example.com", "password": "Test@123456" } | F27: 1. email = data test 2. Các trường required có dữ liệu hợp lệ 3. Nhấn send | G27: 1. Kết quả trả về: { "accessToken": "jwt...", "refreshToken": "refresh...", "user": { "id": "user-id", "email": "hr.test@example.com", "role": "HR", } } | H27: MEDIUM | I27: MAJOR | N27: =IF(OR(IF(M27="",IF(L27="",IF(K27="","",K27), L27),M27)="F")=TRUE,"F", IF(OR( IF(M27="",IF(L27="",IF(K27="","",K27), L27),M27)="PE")=TRUE,"PE", IF(AND(IF(M27="",IF(L27="",IF(K27="","",K27), L27),M27)="")=TRUE,"","P")))
A28: =IF(AND(G28="",G28=""),"",$D$3&"_"&ROW()-13-COUNTBLANK($G$14:G28)) -> AU1_11 | C28: Kiểm tra truyền email có khoảng trắng đầu cuối | D28: { "email": " hr@example.com ", "password": "Test@123456" } | F28: 1. email = data test 2. Các trường required có dữ liệu hợp lệ 3. Nhấn send | G28: 1. Trim space 2. Kết quả trả về: { "accessToken": "jwt...", "refreshToken": "refresh...", "user": { "id": "user-id", "email": "hr.test@example.com", "role": "HR", } } | H28: MEDIUM | I28: MAJOR | N28: =IF(OR(IF(M28="",IF(L28="",IF(K28="","",K28), L28),M28)="F")=TRUE,"F", IF(OR( IF(M28="",IF(L28="",IF(K28="","",K28), L28),M28)="PE")=TRUE,"PE", IF(AND(IF(M28="",IF(L28="",IF(K28="","",K28), L28),M28)="")=TRUE,"","P")))
A29: =IF(AND(G29="",G29=""),"",$D$3&"_"&ROW()-13-COUNTBLANK($G$14:G29)) -> AU1_12 | C29: Kiểm tra truyền email không tồn tại trong DB | D29: { "email": "test@example.com", "password": "Test@123456" } | F29: 1. email = data test 2. Các trường required có dữ liệu hợp lệ 3. Nhấn send | G29: Hiển thị lỗi 400 Bad Request - Request payload is invalid | H29: MEDIUM | I29: MAJOR | N29: =IF(OR(IF(M29="",IF(L29="",IF(K29="","",K29), L29),M29)="F")=TRUE,"F", IF(OR( IF(M29="",IF(L29="",IF(K29="","",K29), L29),M29)="PE")=TRUE,"PE", IF(AND(IF(M29="",IF(L29="",IF(K29="","",K29), L29),M29)="")=TRUE,"","P")))
A30: =IF(AND(G30="",G30=""),"",$D$3&"_"&ROW()-13-COUNTBLANK($G$14:G30)) -> AU1_13 | C30: Kiểm tra truyền email khác kiểu dữ liệu String | D30: { "email": 123, "password": "Test@123456" } | F30: 1. email = data test 2. Các trường required có dữ liệu hợp lệ 3. Nhấn send | G30: Hiển thị lỗi 400 Bad Request - Request payload is invalid | H30: MEDIUM | I30: MAJOR | N30: =IF(OR(IF(M30="",IF(L30="",IF(K30="","",K30), L30),M30)="F")=TRUE,"F", IF(OR( IF(M30="",IF(L30="",IF(K30="","",K30), L30),M30)="PE")=TRUE,"PE", IF(AND(IF(M30="",IF(L30="",IF(K30="","",K30), L30),M30)="")=TRUE,"","P")))
A31: =IF(AND(G31="",G31=""),"",$D$3&"_"&ROW()-13-COUNTBLANK($G$14:G31)) | B31: Kiểm tra trường password
A32: =IF(AND(G32="",G32=""),"",$D$3&"_"&ROW()-13-COUNTBLANK($G$14:G32)) -> AU1_14 | B32: Kiểm tra trường password | C32: Kiểm tra không truyền password | D32: { "email": "hr@example.com" } | F32: 1. password = data test 2. Các trường required có dữ liệu hợp lệ 3. Nhấn send | G32: Hiển thị lỗi 401 Unauthorized - Authentication is required | H32: MEDIUM | I32: MAJOR | N32: =IF(OR(IF(M32="",IF(L32="",IF(K32="","",K32), L32),M32)="F")=TRUE,"F", IF(OR( IF(M32="",IF(L32="",IF(K32="","",K32), L32),M32)="PE")=TRUE,"PE", IF(AND(IF(M32="",IF(L32="",IF(K32="","",K32), L32),M32)="")=TRUE,"","P")))
A33: =IF(AND(G33="",G33=""),"",$D$3&"_"&ROW()-13-COUNTBLANK($G$14:G33)) -> AU1_15 | C33: Kiểm tra truyền password = null | D33: { "email": "hr@example.com", "password": null } | F33: 1. password = data test 2. Các trường required có dữ liệu hợp lệ 3. Nhấn send | G33: Hiển thị lỗi 401 Unauthorized - Authentication is required | H33: MEDIUM | I33: MAJOR | N33: =IF(OR(IF(M33="",IF(L33="",IF(K33="","",K33), L33),M33)="F")=TRUE,"F", IF(OR( IF(M33="",IF(L33="",IF(K33="","",K33), L33),M33)="PE")=TRUE,"PE", IF(AND(IF(M33="",IF(L33="",IF(K33="","",K33), L33),M33)="")=TRUE,"","P")))
A34: =IF(AND(G34="",G34=""),"",$D$3&"_"&ROW()-13-COUNTBLANK($G$14:G34)) -> AU1_16 | C34: Kiểm tra truyền password = rỗng | D34: { "email": "hr@example.com", "password": "" } | F34: 1. password = data test 2. Các trường required có dữ liệu hợp lệ 3. Nhấn send | G34: Hiển thị lỗi 401 Unauthorized - Authentication is required | H34: MEDIUM | I34: MAJOR | N34: =IF(OR(IF(M34="",IF(L34="",IF(K34="","",K34), L34),M34)="F")=TRUE,"F", IF(OR( IF(M34="",IF(L34="",IF(K34="","",K34), L34),M34)="PE")=TRUE,"PE", IF(AND(IF(M34="",IF(L34="",IF(K34="","",K34), L34),M34)="")=TRUE,"","P")))
A35: =IF(AND(G35="",G35=""),"",$D$3&"_"&ROW()-13-COUNTBLANK($G$14:G35)) -> AU1_17 | C35: Kiểm tra truyền password = chuỗi space | D35: { "email": "hr@example.com", "password": " " } | F35: 1. password = data test 2. Các trường required có dữ liệu hợp lệ 3. Nhấn send | G35: Hiển thị lỗi 400 Bad Request - Request payload is invalid | H35: MEDIUM | I35: MAJOR | N35: =IF(OR(IF(M35="",IF(L35="",IF(K35="","",K35), L35),M35)="F")=TRUE,"F", IF(OR( IF(M35="",IF(L35="",IF(K35="","",K35), L35),M35)="PE")=TRUE,"PE", IF(AND(IF(M35="",IF(L35="",IF(K35="","",K35), L35),M35)="")=TRUE,"","P")))
A36: =IF(AND(G36="",G36=""),"",$D$3&"_"&ROW()-13-COUNTBLANK($G$14:G36)) -> AU1_18 | C36: Kiểm tra truyền password tồn tại trong DB | D36: { "email": "hr@example.com", "password": "Test@123456" } | F36: 1. password = data test 2. Các trường required có dữ liệu hợp lệ 3. Nhấn send | G36: 1. Kết quả trả về: { "accessToken": "jwt...", "refreshToken": "refresh...", "user": { "id": "user-id", "email": "hr.test@example.com", "role": "HR", } } | H36: MEDIUM | I36: MAJOR | N36: =IF(OR(IF(M36="",IF(L36="",IF(K36="","",K36), L36),M36)="F")=TRUE,"F", IF(OR( IF(M36="",IF(L36="",IF(K36="","",K36), L36),M36)="PE")=TRUE,"PE", IF(AND(IF(M36="",IF(L36="",IF(K36="","",K36), L36),M36)="")=TRUE,"","P")))
A37: =IF(AND(G37="",G37=""),"",$D$3&"_"&ROW()-13-COUNTBLANK($G$14:G37)) -> AU1_19 | C37: Kiểm tra truyền password có khoảng trắng đầu cuối | D37: { "email": "hr@example.com", "password": " Test@123456 " } | F37: 1. password = data test 2. Các trường required có dữ liệu hợp lệ 3. Nhấn send | G37: Hiển thị lỗi 400 Bad Request - Request payload is invalid | H37: MEDIUM | I37: MAJOR | N37: =IF(OR(IF(M37="",IF(L37="",IF(K37="","",K37), L37),M37)="F")=TRUE,"F", IF(OR( IF(M37="",IF(L37="",IF(K37="","",K37), L37),M37)="PE")=TRUE,"PE", IF(AND(IF(M37="",IF(L37="",IF(K37="","",K37), L37),M37)="")=TRUE,"","P")))
A38: =IF(AND(G38="",G38=""),"",$D$3&"_"&ROW()-13-COUNTBLANK($G$14:G38)) -> AU1_20 | C38: Kiểm tra truyền password không tồn tại trong DB | D38: { "email": "hr@example.com", "password": "123456" } | F38: 1. password = data test 2. Các trường required có dữ liệu hợp lệ 3. Nhấn send | G38: Hiển thị lỗi 400 Bad Request - Request payload is invalid | H38: MEDIUM | I38: MAJOR | N38: =IF(OR(IF(M38="",IF(L38="",IF(K38="","",K38), L38),M38)="F")=TRUE,"F", IF(OR( IF(M38="",IF(L38="",IF(K38="","",K38), L38),M38)="PE")=TRUE,"PE", IF(AND(IF(M38="",IF(L38="",IF(K38="","",K38), L38),M38)="")=TRUE,"","P")))
A39: =IF(AND(G39="",G39=""),"",$D$3&"_"&ROW()-13-COUNTBLANK($G$14:G39)) -> AU1_21 | C39: Kiểm tra truyền password khác kiểu dữ liệu String | D39: { "email": "hr@example.com", "password": 123 } | F39: 1. password = data test 2. Các trường required có dữ liệu hợp lệ 3. Nhấn send | G39: Hiển thị lỗi 400 Bad Request - Request payload is invalid | H39: MEDIUM | I39: MAJOR | N39: =IF(OR(IF(M39="",IF(L39="",IF(K39="","",K39), L39),M39)="F")=TRUE,"F", IF(OR( IF(M39="",IF(L39="",IF(K39="","",K39), L39),M39)="PE")=TRUE,"PE", IF(AND(IF(M39="",IF(L39="",IF(K39="","",K39), L39),M39)="")=TRUE,"","P")))
A40: =IF(AND(G40="",G40=""),"",$D$3&"_"&ROW()-13-COUNTBLANK($G$14:G40)) | B40: Chức năng
A41: =IF(AND(G41="",G41=""),"",$D$3&"_"&ROW()-13-COUNTBLANK($G$14:G41)) -> AU1_22 | B41: Kiểm tra khi API thực thi thành công | C41: Kiểm tra truyền email và password đã tồn tại trong DB | D41: { "email": "hr@example.com", "password": "Test@123456" } | F41: 1. Nhập các trường = data test 2. Send request | G41: 1. Kết quả trả về: { "accessToken": "jwt...", "refreshToken": "refresh...", "user": { "id": "user-id", "email": "hr.test@example.com", "role": "HR", } } | H41: HIGH | I41: MAJOR | N41: =IF(OR(IF(M41="",IF(L41="",IF(K41="","",K41), L41),M41)="F")=TRUE,"F", IF(OR( IF(M41="",IF(L41="",IF(K41="","",K41), L41),M41)="PE")=TRUE,"PE", IF(AND(IF(M41="",IF(L41="",IF(K41="","",K41), L41),M41)="")=TRUE,"","P")))
...

Sheet API_lay_thong_tin_user
C1: KỊCH BẢN KIỂM THỬ *
C2: Tên màn hình/Tên chức năng | D2: API lấy thông tin user
C3: Mã testcase | D3: AU2
C4: Số testcase đạt (P) | D4: =COUNTIF($N$13:$N$169,"P") -> 0
C5: Số testcase không đạt (F) | D5: =COUNTIF($N$13:$N$169,"F") -> 0
C6: Số testcase đang xem xét (PE) | D6: =COUNTIF($N$13:$N$169,"PE") -> 0
C7: Số testcase chưa test | D7: =D8-D4-D5-D6 -> 11
C8: Tổng số testcase | D8: =COUNTA($G$13:$G$169) -> 11
A10: ID | B10: Mục đích kiểm thử | C10: Trường hợp kiểm thử | D10: Data test | E10: cURL | F10: Các bước thực hiện | G10: Kết quả mong muốn | H10: Thứ tự ưu tiên | I10: Mức độ nghiêm trọng | J10: Hình ảnh | K10: Manual test | N10: Kết quả test (M) | O10: Mã lỗi | P10: Ghi chú
K11: Postman
K12: Lần 1 | L12: Lần 2 | M12: Lần 3
B13: Chức năng: Lấy thông tin user hiện tại Method: GET MT alpha: Url: http://192.168.1.131:3002/api/auth/me Authorization: hợp lệ
A14: =IF(AND(G14="",G14=""),"",$D$3&"_"&ROW()-13-COUNTBLANK($G$14:G14)) | B14: Giao diện (Phần này viết các trường hợp kiểm thử cho giao diên chung và các giao diện cho các control)
A15: =IF(AND(G15="",G15=""),"",$D$3&"_"&ROW()-13-COUNTBLANK($G$14:G15)) | B15: Kiểm tra truyền vào URL
A16: =IF(AND(G16="",G16=""),"",$D$3&"_"&ROW()-13-COUNTBLANK($G$14:G16)) -> AU2_1 | B16: Kiểm tra path | C16: Sai đường dẫn | D16: http://192.168.1.131:3002/api/auth/me12 | F16: 1. Truyền sai path 2. Các trường required, method có dữ liệu hợp lệ | G16: 1. Kết quả trả về: status 404 | H16: MEDIUM | I16: MAJOR | N16: =IF(OR(IF(M16="",IF(L16="",IF(K16="","",K16), L16),M16)="F")=TRUE,"F", IF(OR( IF(M16="",IF(L16="",IF(K16="","",K16), L16),M16)="PE")=TRUE,"PE", IF(AND(IF(M16="",IF(L16="",IF(K16="","",K16), L16),M16)="")=TRUE,"","P")))
A17: =IF(AND(G17="",G17=""),"",$D$3&"_"&ROW()-13-COUNTBLANK($G$14:G17)) -> AU2_2 | C17: Không nhập đường dẫn | D17: Enter URL or text = null | F17: 1. Không truyền path 2. Các trường required, method có dữ liệu hợp lệ | G17: 1. Kết quả trả về: status 404 | H17: MEDIUM | I17: MAJOR | N17: =IF(OR(IF(M17="",IF(L17="",IF(K17="","",K17), L17),M17)="F")=TRUE,"F", IF(OR( IF(M17="",IF(L17="",IF(K17="","",K17), L17),M17)="PE")=TRUE,"PE", IF(AND(IF(M17="",IF(L17="",IF(K17="","",K17), L17),M17)="")=TRUE,"","P")))
A18: =IF(AND(G18="",G18=""),"",$D$3&"_"&ROW()-13-COUNTBLANK($G$14:G18)) -> AU2_3 | C18: Đường dẫn đúng (pre: 1.Có tài khoản : email = hr@example.com, password = Test@123456 2. Login với acc trên để ấy accessToken từ api | D18: accessToken: eyJhbGciOiJIUzI1NiIsInR5cCI6IkpXVCJ9.eyJzdWIiOiJjMDFmMTJmMC1iODVkLTRlMjItODQyYS0wMzllOTY3NDJhNWMiLCJlbWFpbCI6ImhyLnRlc3RAZXhhbXBsZS5jb20iLCJyb2xlIjoiSFIiLCJpYXQiOjE3ODQxOTU4ODEsImV4cCI6MTc4NDE5Njc4MX0.-ODJkpCGjpHF3sN1VKlRGFKD5rvvM2cWNMZhkcl-6IU | F18: 1. Truyền path đúng 2. Các trường required, method có dữ liệu hợp lệ | G18: 1. Kết quả trả về: { "id": "id", "email": "hr@example.com", "name": "HR Test", "role": "HR" } | H18: HIGH | I18: MAJOR | N18: =IF(OR(IF(M18="",IF(L18="",IF(K18="","",K18), L18),M18)="F")=TRUE,"F", IF(OR( IF(M18="",IF(L18="",IF(K18="","",K18), L18),M18)="PE")=TRUE,"PE", IF(AND(IF(M18="",IF(L18="",IF(K18="","",K18), L18),M18)="")=TRUE,"","P")))
A19: =IF(AND(G19="",G19=""),"",$D$3&"_"&ROW()-13-COUNTBLANK($G$14:G19)) -> AU2_4 | B19: Kiểm tra method | C19: Kiểm tra truyền đúng method | D19: Method: GET accessToken: eyJhbGciOiJIUzI1NiIsInR5cCI6IkpXVCJ9.eyJzdWIiOiJjMDFmMTJmMC1iODVkLTRlMjItODQyYS0wMzllOTY3NDJhNWMiLCJlbWFpbCI6ImhyLnRlc3RAZXhhbXBsZS5jb20iLCJyb2xlIjoiSFIiLCJpYXQiOjE3ODQxOTU4ODEsImV4cCI6MTc4NDE5Njc4MX0.-ODJkpCGjpHF3sN1VKlRGFKD5rvvM2cWNMZhkcl-6IU | F19: 1. Truyền path đúng 2. Truyền method đúng 3. Các trường required có dữ liệu hợp lệ | G19: 1. Kết quả trả về: { "id": "id", "email": "hr@example.com", "name": "HR Test", "role": "HR" } | H19: HIGH | I19: MAJOR
A20: =IF(AND(G20="",G20=""),"",$D$3&"_"&ROW()-13-COUNTBLANK($G$14:G20)) -> AU2_5 | C20: Kiểm tra truyền sai method | D20: Method: POST accessToken: eyJhbGciOiJIUzI1NiIsInR5cCI6IkpXVCJ9.eyJzdWIiOiJjMDFmMTJmMC1iODVkLTRlMjItODQyYS0wMzllOTY3NDJhNWMiLCJlbWFpbCI6ImhyLnRlc3RAZXhhbXBsZS5jb20iLCJyb2xlIjoiSFIiLCJpYXQiOjE3ODQxOTU4ODEsImV4cCI6MTc4NDE5Njc4MX0.-ODJkpCGjpHF3sN1VKlRGFKD5rvvM2cWNMZhkcl-6IU | F20: 1. Truyền path đúng 2. Truyền method sai 3. Các trường required có dữ liệu hợp lệ | G20: 1. Kết quả trả về: status 404 | H20: MEDIUM | I20: MAJOR
A21: =IF(AND(G21="",G21=""),"",$D$3&"_"&ROW()-13-COUNTBLANK($G$14:G21)) | B21: Kiểm tra validate các trường thông tin
A22: =IF(AND(G22="",G22=""),"",$D$3&"_"&ROW()-13-COUNTBLANK($G$14:G22)) | B22: Truyền Access Token vào Authorization
A23: =IF(AND(G23="",G23=""),"",$D$3&"_"&ROW()-13-COUNTBLANK($G$14:G23)) -> AU2_6 | B23: Kiểm tra truyền Access Token | C23: Ko truyền Access Token | D23: AccessToken = null | F23: 1. accessToken = datatest 2. Nhấn send | G23: Hiển thị lỗi 401 Unauthorized - Authentication is required | H23: MEDIUM | I23: MAJOR | N23: =IF(OR(IF(M23="",IF(L23="",IF(K23="","",K23), L23),M23)="F")=TRUE,"F", IF(OR( IF(M23="",IF(L23="",IF(K23="","",K23), L23),M23)="PE")=TRUE,"PE", IF(AND(IF(M23="",IF(L23="",IF(K23="","",K23), L23),M23)="")=TRUE,"","P")))
A24: =IF(AND(G24="",G24=""),"",$D$3&"_"&ROW()-13-COUNTBLANK($G$14:G24)) -> AU2_7 | C24: Truyền Access Token (còn expires) | D24: accessToken: eyJhbGciOiJIUzI1NiIsInR5cCI6IkpXVCJ9.eyJzdWIiOiJjMDFmMTJmMC1iODVkLTRlMjItODQyYS0wMzllOTY3NDJhNWMiLCJlbWFpbCI6ImhyLnRlc3RAZXhhbXBsZS5jb20iLCJyb2xlIjoiSFIiLCJpYXQiOjE3ODQxOTU4ODEsImV4cCI6MTc4NDE5Njc4MX0.-ODJkpCGjpHF3sN1VKlRGFKD5rvvM2cWNMZhkcl-6IU | E24: ` | F24: 1. accessToken = datatest 2. Nhấn send | G24: 1. Kết quả trả về: { "id": "id", "email": "hr@example.com", "name": "HR Test", "role": "HR" } | H24: HIGH | I24: MAJOR | N24: =IF(OR(IF(M24="",IF(L24="",IF(K24="","",K24), L24),M24)="F")=TRUE,"F", IF(OR( IF(M24="",IF(L24="",IF(K24="","",K24), L24),M24)="PE")=TRUE,"PE", IF(AND(IF(M24="",IF(L24="",IF(K24="","",K24), L24),M24)="")=TRUE,"","P")))
A25: =IF(AND(G25="",G25=""),"",$D$3&"_"&ROW()-13-COUNTBLANK($G$14:G25)) -> AU2_8 | C25: Truyền Access Token (đã hết expires) | D25: accessToken: eyJhbGciOiJIUzI1NiIsInR5cCI6IkpXVCJ9.eyJzdWIiOiJjMDFmMTJmMC1iODVkLTRlMjItODQyYS0wMzllOTY3NDJhNWMiLCJlbWFpbCI6ImhyLnRlc3RAZXhhbXBsZS5jb20iLCJyb2xlIjoiSFIiLCJpYXQiOjE3ODQxOTU4ODEsImV4cCI6MTc4NDE5Njc4MX0.-ODJkpCGjpHF3sN1VKlRGFKD5rvvM2cWNMZhkcl-6IU | F25: 1. accessToken = datatest 2. Nhấn send | G25: Hiển thị lỗi 401 Unauthorized - Authentication is required | H25: MEDIUM | I25: MAJOR | N25: =IF(OR(IF(M25="",IF(L25="",IF(K25="","",K25), L25),M25)="F")=TRUE,"F", IF(OR( IF(M25="",IF(L25="",IF(K25="","",K25), L25),M25)="PE")=TRUE,"PE", IF(AND(IF(M25="",IF(L25="",IF(K25="","",K25), L25),M25)="")=TRUE,"","P")))
A26: =IF(AND(G26="",G26=""),"",$D$3&"_"&ROW()-13-COUNTBLANK($G$14:G26)) | B26: Chức năng
A27: =IF(AND(G27="",G27=""),"",$D$3&"_"&ROW()-13-COUNTBLANK($G$14:G27)) -> AU2_9 | B27: Kiểm tra lấy thông tin user thành công | C27: Kiểm tra truyền accessToken còn hạn | D27: accessToken: eyJhbGciOiJIUzI1NiIsInR5cCI6IkpXVCJ9.eyJzdWIiOiJjMDFmMTJmMC1iODVkLTRlMjItODQyYS0wMzllOTY3NDJhNWMiLCJlbWFpbCI6ImhyLnRlc3RAZXhhbXBsZS5jb20iLCJyb2xlIjoiSFIiLCJpYXQiOjE3ODQxOTU4ODEsImV4cCI6MTc4NDE5Njc4MX0.-ODJkpCGjpHF3sN1VKlRGFKD5rvvM2cWNMZhkcl-6IU | F27: 1. Nhập các trường = data test 2. Send request | G27: 1. Kết quả trả về: { "id": "id", "email": "hr@example.com", "name": "HR Test", "role": "HR" } | H27: HIGH | I27: MAJOR | N27: =IF(OR(IF(M27="",IF(L27="",IF(K27="","",K27), L27),M27)="F")=TRUE,"F", IF(OR( IF(M27="",IF(L27="",IF(K27="","",K27), L27),M27)="PE")=TRUE,"PE", IF(AND(IF(M27="",IF(L27="",IF(K27="","",K27), L27),M27)="")=TRUE,"","P")))
A28: =IF(AND(G28="",G28=""),"",$D$3&"_"&ROW()-13-COUNTBLANK($G$14:G28)) -> AU2_10 | B28: Kiểm tra lấy thông tin user không thành công | C28: Kiểm tra truyền accessToken hết hạn | D28: accessToken: eyJhbGciOiJIUzI1NiIsInR5cCI6IkpXVCJ9.eyJzdWIiOiJjMDFmMTJmMC1iODVkLTRlMjItODQyYS0wMzllOTY3NDJhNWMiLCJlbWFpbCI6ImhyLnRlc3RAZXhhbXBsZS5jb20iLCJyb2xlIjoiSFIiLCJpYXQiOjE3ODQxOTU4ODEsImV4cCI6MTc4NDE5Njc4MX0.-ODJkpCGjpHF3sN1VKlRGFKD5rvvM2cWNMZhkcl-6IU | F28: 1. Nhập các trường = data test 2. Send request | G28: Hiển thị lỗi 401 Unauthorized - Authentication is required | H28: HIGH | I28: MAJOR | N28: =IF(OR(IF(M28="",IF(L28="",IF(K28="","",K28), L28),M28)="F")=TRUE,"F", IF(OR( IF(M28="",IF(L28="",IF(K28="","",K28), L28),M28)="PE")=TRUE,"PE", IF(AND(IF(M28="",IF(L28="",IF(K28="","",K28), L28),M28)="")=TRUE,"","P")))
A29: =IF(AND(G29="",G29=""),"",$D$3&"_"&ROW()-13-COUNTBLANK($G$14:G29)) -> AU2_11 | B29: Kiểm tra thực thi API khi có lỗi server | C29: Server lỗi | D29: accessToken: eyJhbGciOiJIUzI1NiIsInR5cCI6IkpXVCJ9.eyJzdWIiOiJjMDFmMTJmMC1iODVkLTRlMjItODQyYS0wMzllOTY3NDJhNWMiLCJlbWFpbCI6ImhyLnRlc3RAZXhhbXBsZS5jb20iLCJyb2xlIjoiSFIiLCJpYXQiOjE3ODQxOTU4ODEsImV4cCI6MTc4NDE5Njc4MX0.-ODJkpCGjpHF3sN1VKlRGFKD5rvvM2cWNMZhkcl-6IU | F29: 1. Nhập các trường = data test 2. Send request | G29: Hiển thị lỗi 500 Internal Server Error - Request could not be completed. Please retry later | H29: HIGH | I29: MAJOR
A30: =IF(AND(G30="",G30=""),"",$D$3&"_"&ROW()-13-COUNTBLANK($G$14:G30)) | B30: Chức năng ảnh hưởng
A31: =IF(AND(G31="",G31=""),"",$D$3&"_"&ROW()-13-COUNTBLANK($G$14:G31)) | B31: N/A | N31: =IF(OR(IF(M31="",IF(L31="",IF(K31="","",K31), L31),M31)="F")=TRUE,"F", IF(OR( IF(M31="",IF(L31="",IF(K31="","",K31), L31),M31)="PE")=TRUE,"PE", IF(AND(IF(M31="",IF(L31="",IF(K31="","",K31), L31),M31)="")=TRUE,"","P")))
A32: =IF(AND(G32="",G32=""),"",$D$3&"_"&ROW()-13-COUNTBLANK($G$14:G32)) | B32: An toàn thông tin (Các trường hợp kiểm thử đảm bảo an toàn thông tin theo hướng dẫn kiểm thử an toàn thông tin)
A33: =IF(AND(G33="",G33=""),"",$D$3&"_"&ROW()-13-COUNTBLANK($G$14:G33)) | B33: N/A | N33: =IF(OR(IF(M33="",IF(L33="",IF(K33="","",K33), L33),M33)="F")=TRUE,"F", IF(OR( IF(M33="",IF(L33="",IF(K33="","",K33), L33),M33)="PE")=TRUE,"PE", IF(AND(IF(M33="",IF(L33="",IF(K33="","",K33), L33),M33)="")=TRUE,"","P")))

Sheet API_lam_moi_phien_đn
C1: KỊCH BẢN KIỂM THỬ *
C2: Tên màn hình/Tên chức năng | D2: API làm mới phiên đăng nhập
C3: Mã testcase | D3: AU3
C4: Số testcase đạt (P) | D4: =COUNTIF($N$13:$N$175,"P") -> 0
C5: Số testcase không đạt (F) | D5: =COUNTIF($N$13:$N$175,"F") -> 0
C6: Số testcase đang xem xét (PE) | D6: =COUNTIF($N$13:$N$175,"PE") -> 0
C7: Số testcase chưa test | D7: =D8-D4-D5-D6 -> 17
C8: Tổng số testcase | D8: =COUNTA($G$13:$G$175) -> 17
A10: ID | B10: Mục đích kiểm thử | C10: Trường hợp kiểm thử | D10: Data test | E10: cURL | F10: Các bước thực hiện | G10: Kết quả mong muốn | H10: Thứ tự ưu tiên | I10: Mức độ nghiêm trọng | J10: Hình ảnh | K10: Manual test | N10: Kết quả test (M) | O10: Mã lỗi | P10: Ghi chú
K11: Postman
K12: Lần 1 | L12: Lần 2 | M12: Lần 3
B13: Chức năng: Làm mới phiên đăng nhập Method: POST MT alpha: Url: http://192.168.1.131:3002/api/auth/refresh body { "refreshToken": "rt_GTNHaj8Q3fvqfUYRfvNQzFCNYHTQn_8xvmfdIEPd2OQpcEufMxouZsiaB53ZI2XrnTq8d9rfULxdtyL7Ze5JnQ" }
A14: =IF(AND(G14="",G14=""),"",$D$3&"_"&ROW()-13-COUNTBLANK($G$14:G14)) | B14: Giao diện (Phần này viết các trường hợp kiểm thử cho giao diên chung và các giao diện cho các control)
A15: =IF(AND(G15="",G15=""),"",$D$3&"_"&ROW()-13-COUNTBLANK($G$14:G15)) | B15: Kiểm tra truyền vào URL
A16: =IF(AND(G16="",G16=""),"",$D$3&"_"&ROW()-13-COUNTBLANK($G$14:G16)) -> AU3_1 | B16: Kiểm tra path | C16: Sai đường dẫn | D16: http://192.168.1.131:3002/api/auth/refresh12 | F16: 1. Truyền sai path 2. Các trường required, method có dữ liệu hợp lệ | G16: 1. Kết quả trả về: status 404 | H16: MEDIUM | I16: MAJOR | N16: =IF(OR(IF(M16="",IF(L16="",IF(K16="","",K16), L16),M16)="F")=TRUE,"F", IF(OR( IF(M16="",IF(L16="",IF(K16="","",K16), L16),M16)="PE")=TRUE,"PE", IF(AND(IF(M16="",IF(L16="",IF(K16="","",K16), L16),M16)="")=TRUE,"","P")))
A17: =IF(AND(G17="",G17=""),"",$D$3&"_"&ROW()-13-COUNTBLANK($G$14:G17)) -> AU3_2 | C17: Không nhập đường dẫn | D17: Enter URL or text = null | F17: 1. Không truyền path 2. Các trường required, method có dữ liệu hợp lệ | G17: 1. Kết quả trả về: status 404 | H17: MEDIUM | I17: MAJOR | N17: =IF(OR(IF(M17="",IF(L17="",IF(K17="","",K17), L17),M17)="F")=TRUE,"F", IF(OR( IF(M17="",IF(L17="",IF(K17="","",K17), L17),M17)="PE")=TRUE,"PE", IF(AND(IF(M17="",IF(L17="",IF(K17="","",K17), L17),M17)="")=TRUE,"","P")))
A18: =IF(AND(G18="",G18=""),"",$D$3&"_"&ROW()-13-COUNTBLANK($G$14:G18)) -> AU3_3 | C18: Đường dẫn đúng (pre: 1.Có tài khoản : email = hr@example.com, password = Test@123456 2. Login với acc trên để ấy refreshToken từ api | D18: { "refreshToken": "rt_GTNHaj8Q3fvqfUYRfvNQzFCNYHTQn_8xvmfdIEPd2OQpcEufMxouZsiaB53ZI2XrnTq8d9rfULxdtyL7Ze5JnQ" } | F18: 1. Truyền path đúng 2. Các trường required, method có dữ liệu hợp lệ | G18: 1. Kết quả trả về: { "accessToken": "jwt...", "refreshToken": "refresh..." } | H18: HIGH | I18: MAJOR | N18: =IF(OR(IF(M18="",IF(L18="",IF(K18="","",K18), L18),M18)="F")=TRUE,"F", IF(OR( IF(M18="",IF(L18="",IF(K18="","",K18), L18),M18)="PE")=TRUE,"PE", IF(AND(IF(M18="",IF(L18="",IF(K18="","",K18), L18),M18)="")=TRUE,"","P")))
A19: =IF(AND(G19="",G19=""),"",$D$3&"_"&ROW()-13-COUNTBLANK($G$14:G19)) -> AU3_4 | B19: Kiểm tra method | C19: Kiểm tra truyền đúng method | D19: Method: POST { "refreshToken": "rt_GTNHaj8Q3fvqfUYRfvNQzFCNYHTQn_8xvmfdIEPd2OQpcEufMxouZsiaB53ZI2XrnTq8d9rfULxdtyL7Ze5JnQ" } | F19: 1. Truyền path đúng 2. Truyền method đúng 3. Các trường required có dữ liệu hợp lệ | G19: 1. Kết quả trả về: { "accessToken": "jwt...", "refreshToken": "refresh..." } | H19: HIGH | I19: MAJOR
A20: =IF(AND(G20="",G20=""),"",$D$3&"_"&ROW()-13-COUNTBLANK($G$14:G20)) -> AU3_5 | C20: Kiểm tra truyền sai method | D20: Method: GET { "refreshToken": "rt_GTNHaj8Q3fvqfUYRfvNQzFCNYHTQn_8xvmfdIEPd2OQpcEufMxouZsiaB53ZI2XrnTq8d9rfULxdtyL7Ze5JnQ" } | F20: 1. Truyền path đúng 2. Truyền method sai 3. Các trường required có dữ liệu hợp lệ | G20: 1. Kết quả trả về: status 404 | H20: MEDIUM | I20: MAJOR
A21: =IF(AND(G21="",G21=""),"",$D$3&"_"&ROW()-13-COUNTBLANK($G$14:G21)) | B21: Kiểm tra validate các trường thông tin
A22: =IF(AND(G22="",G22=""),"",$D$3&"_"&ROW()-13-COUNTBLANK($G$14:G22)) | B22: Kiểm tra trường refeshToken
A23: =IF(AND(G23="",G23=""),"",$D$3&"_"&ROW()-13-COUNTBLANK($G$14:G23)) -> AU3_6 | B23: Kiểm tra trường refeshToken | C23: Kiểm tra không truyền refreshToken | D23: { } | F23: 1. Ko truyền refreshToken 2. Các trường required có dữ liệu hợp lệ 3. Nhấn send | G23: Hiển thị lỗi 400 Bad Request - Message: "Request payload is invalid" | H23: MEDIUM | I23: MAJOR | N23: =IF(OR(IF(M23="",IF(L23="",IF(K23="","",K23), L23),M23)="F")=TRUE,"F", IF(OR( IF(M23="",IF(L23="",IF(K23="","",K23), L23),M23)="PE")=TRUE,"PE", IF(AND(IF(M23="",IF(L23="",IF(K23="","",K23), L23),M23)="")=TRUE,"","P")))
A24: =IF(AND(G24="",G24=""),"",$D$3&"_"&ROW()-13-COUNTBLANK($G$14:G24)) -> AU3_7 | C24: Kiểm tra truyền refreshToken = null | D24: { "refreshToken": null } | F24: 1. refreshToken = data test 2. Các trường required có dữ liệu hợp lệ 3. Nhấn send | G24: Hiển thị lỗi 400 Bad Request - Message: "Request payload is invalid" | H24: MEDIUM | I24: MAJOR | N24: =IF(OR(IF(M24="",IF(L24="",IF(K24="","",K24), L24),M24)="F")=TRUE,"F", IF(OR( IF(M24="",IF(L24="",IF(K24="","",K24), L24),M24)="PE")=TRUE,"PE", IF(AND(IF(M24="",IF(L24="",IF(K24="","",K24), L24),M24)="")=TRUE,"","P")))
A25: =IF(AND(G25="",G25=""),"",$D$3&"_"&ROW()-13-COUNTBLANK($G$14:G25)) -> AU3_8 | C25: Kiểm tra truyền refreshToken = rỗng | D25: { "refreshToken": "" } | F25: 1. refreshToken = data test 2. Các trường required có dữ liệu hợp lệ 3. Nhấn send | G25: Hiển thị lỗi 400 Bad Request - Message: "Request payload is invalid" | H25: MEDIUM | I25: MAJOR | N25: =IF(OR(IF(M25="",IF(L25="",IF(K25="","",K25), L25),M25)="F")=TRUE,"F", IF(OR( IF(M25="",IF(L25="",IF(K25="","",K25), L25),M25)="PE")=TRUE,"PE", IF(AND(IF(M25="",IF(L25="",IF(K25="","",K25), L25),M25)="")=TRUE,"","P")))
A26: =IF(AND(G26="",G26=""),"",$D$3&"_"&ROW()-13-COUNTBLANK($G$14:G26)) -> AU3_9 | C26: Kiểm tra truyền refreshToken = chuỗi space | D26: { "refreshToken": " " } | F26: 1. refreshToken = data test 2. Các trường required có dữ liệu hợp lệ 3. Nhấn send | G26: Hiển thị lỗi 401 Unauthorized - Authentication is required | H26: MEDIUM | I26: MAJOR | N26: =IF(OR(IF(M26="",IF(L26="",IF(K26="","",K26), L26),M26)="F")=TRUE,"F", IF(OR( IF(M26="",IF(L26="",IF(K26="","",K26), L26),M26)="PE")=TRUE,"PE", IF(AND(IF(M26="",IF(L26="",IF(K26="","",K26), L26),M26)="")=TRUE,"","P")))
A27: =IF(AND(G27="",G27=""),"",$D$3&"_"&ROW()-13-COUNTBLANK($G$14:G27)) -> AU3_10 | C27: Kiểm tra truyền refreshToken được cấp sau khi đăng nhập | D27: { "refreshToken": "rt_GTNHaj8Q3fvqfUYRfvNQzFCNYHTQn_8xvmfdIEPd2OQpcEufMxouZsiaB53ZI2XrnTq8d9rfULxdtyL7Ze5JnQ" } | F27: 1. refreshToken = data test 2. Các trường required có dữ liệu hợp lệ 3. Nhấn send | G27: 1. Kết quả trả về: { "accessToken": "jwt...", "refreshToken": "refresh..." } | H27: HIGH | I27: MAJOR | N27: =IF(OR(IF(M27="",IF(L27="",IF(K27="","",K27), L27),M27)="F")=TRUE,"F", IF(OR( IF(M27="",IF(L27="",IF(K27="","",K27), L27),M27)="PE")=TRUE,"PE", IF(AND(IF(M27="",IF(L27="",IF(K27="","",K27), L27),M27)="")=TRUE,"","P")))
A28: =IF(AND(G28="",G28=""),"",$D$3&"_"&ROW()-13-COUNTBLANK($G$14:G28)) -> AU3_11 | C28: Kiểm tra truyền password refreshToken không tồn tại trong hệ thống | D28: { "refreshToken": "rt_GTNHaj8Q3fvqfUYRfvNQzFCNYHTQn_8xvmfdIEPd2OQpcEufMxouZsiaB53ZI2XrnTq8d9rfULxdtyL7Ze5JnQ12" } | F28: 1. refreshToken = data test 2. Các trường required có dữ liệu hợp lệ 3. Nhấn send | G28: Hiển thị lỗi 401 Unauthorized - Authentication is required | H28: MEDIUM | I28: MAJOR | N28: =IF(OR(IF(M28="",IF(L28="",IF(K28="","",K28), L28),M28)="F")=TRUE,"F", IF(OR( IF(M28="",IF(L28="",IF(K28="","",K28), L28),M28)="PE")=TRUE,"PE", IF(AND(IF(M28="",IF(L28="",IF(K28="","",K28), L28),M28)="")=TRUE,"","P")))
A29: =IF(AND(G29="",G29=""),"",$D$3&"_"&ROW()-13-COUNTBLANK($G$14:G29)) -> AU3_12 | C29: Kiểm tra truyền refreshToken khác kiểu dữ liệu String | D29: { "refreshToken": 123 } | F29: 1. refreshToken = data test 2. Các trường required có dữ liệu hợp lệ 3. Nhấn send | G29: Hiển thị lỗi 401 Unauthorized - Authentication is required | H29: MEDIUM | I29: MAJOR | N29: =IF(OR(IF(M29="",IF(L29="",IF(K29="","",K29), L29),M29)="F")=TRUE,"F", IF(OR( IF(M29="",IF(L29="",IF(K29="","",K29), L29),M29)="PE")=TRUE,"PE", IF(AND(IF(M29="",IF(L29="",IF(K29="","",K29), L29),M29)="")=TRUE,"","P")))
A30: =IF(AND(G30="",G30=""),"",$D$3&"_"&ROW()-13-COUNTBLANK($G$14:G30)) | B30: Chức năng
A31: =IF(AND(G31="",G31=""),"",$D$3&"_"&ROW()-13-COUNTBLANK($G$14:G31)) -> AU3_13 | B31: Kiểm tra khi API thực thi thành công | C31: Kiểm tra truyền refreshToken đã cấp khi đăng nhập | D31: { "refreshToken": "rt_GTNHaj8Q3fvqfUYRfvNQzFCNYHTQn_8xvmfdIEPd2OQpcEufMxouZsiaB53ZI2XrnTq8d9rfULxdtyL7Ze5JnQ" } | F31: 1. Nhập các trường = data test 2. Send request | G31: 1. Kết quả trả về: { "accessToken": "jwt...", "refreshToken": "refresh..." } | H31: HIGH | I31: MAJOR | N31: =IF(OR(IF(M31="",IF(L31="",IF(K31="","",K31), L31),M31)="F")=TRUE,"F", IF(OR( IF(M31="",IF(L31="",IF(K31="","",K31), L31),M31)="PE")=TRUE,"PE", IF(AND(IF(M31="",IF(L31="",IF(K31="","",K31), L31),M31)="")=TRUE,"","P")))
A32: =IF(AND(G32="",G32=""),"",$D$3&"_"&ROW()-13-COUNTBLANK($G$14:G32)) -> AU3_14 | B32: Kiểm tra khi API thực thi không thành công | C32: Kiểm tra truyền refreshToken không tồn tại | D32: { "refreshToken": "rt_GTNHaj8Q3fvqfUYRfvNQzFCNYHTQn_8xvmfdIEPd2OQpcEufMxouZsiaB53ZI2XrnTq8d9rfULxdtyL7Ze5JnQ12" } | F32: 1. Nhập các trường = data test 2. Send request | G32: Hiển thị lỗi 401 Unauthorized - Authentication is required | H32: HIGH | I32: MAJOR | N32: =IF(OR(IF(M32="",IF(L32="",IF(K32="","",K32), L32),M32)="F")=TRUE,"F", IF(OR( IF(M32="",IF(L32="",IF(K32="","",K32), L32),M32)="PE")=TRUE,"PE", IF(AND(IF(M32="",IF(L32="",IF(K32="","",K32), L32),M32)="")=TRUE,"","P")))
A33: =IF(AND(G33="",G33=""),"",$D$3&"_"&ROW()-13-COUNTBLANK($G$14:G33)) -> AU3_15 | C33: Kiểm tra khi API thực thi khi server lỗi | D33: { "refreshToken": "rt_GTNHaj8Q3fvqfUYRfvNQzFCNYHTQn_8xvmfdIEPd2OQpcEufMxouZsiaB53ZI2XrnTq8d9rfULxdtyL7Ze5JnQ12" } | F33: 1. Nhập các trường = data test 2. Send request | G33: Hiển thị lỗi 401 Unauthorized - Authentication is required | H33: HIGH | I33: MAJOR | N33: =IF(OR(IF(M33="",IF(L33="",IF(K33="","",K33), L33),M33)="F")=TRUE,"F", IF(OR( IF(M33="",IF(L33="",IF(K33="","",K33), L33),M33)="PE")=TRUE,"PE", IF(AND(IF(M33="",IF(L33="",IF(K33="","",K33), L33),M33)="")=TRUE,"","P")))
A34: =IF(AND(G34="",G34=""),"",$D$3&"_"&ROW()-13-COUNTBLANK($G$14:G34)) -> AU3_16 | B34: Kiểm tra send request nhiều lần/phút | C34: Kiểm tra send request nhỏ hơn hoặc bằng 30 lần/phút | D34: { "refreshToken": "rt_GTNHaj8Q3fvqfUYRfvNQzFCNYHTQn_8xvmfdIEPd2OQpcEufMxouZsiaB53ZI2XrnTq8d9rfULxdtyL7Ze5JnQ" } | F34: 1. Nhập các trường = data test 2. Send request 30 lần | G34: 1. Kết quả trả về: { "accessToken": "jwt...", "refreshToken": "refresh..." } | H34: HIGH | I34: MAJOR | N34: =IF(OR(IF(M34="",IF(L34="",IF(K34="","",K34), L34),M34)="F")=TRUE,"F", IF(OR( IF(M34="",IF(L34="",IF(K34="","",K34), L34),M34)="PE")=TRUE,"PE", IF(AND(IF(M34="",IF(L34="",IF(K34="","",K34), L34),M34)="")=TRUE,"","P")))
A35: =IF(AND(G35="",G35=""),"",$D$3&"_"&ROW()-13-COUNTBLANK($G$14:G35)) -> AU3_17 | C35: Kiểm tra send request nhiều hơn 30 lần/phút | D35: { "refreshToken": "rt_GTNHaj8Q3fvqfUYRfvNQzFCNYHTQn_8xvmfdIEPd2OQpcEufMxouZsiaB53ZI2XrnTq8d9rfULxdtyL7Ze5JnQ" } | F35: 1. Nhập các trường = data test 2. Send request 31 lần | G35: Hiển thị lỗi 429 Too many Request - Too many requests. Please retry later | H35: HIGH | I35: MAJOR | N35: =IF(OR(IF(M35="",IF(L35="",IF(K35="","",K35), L35),M35)="F")=TRUE,"F", IF(OR( IF(M35="",IF(L35="",IF(K35="","",K35), L35),M35)="PE")=TRUE,"PE", IF(AND(IF(M35="",IF(L35="",IF(K35="","",K35), L35),M35)="")=TRUE,"","P")))
A36: =IF(AND(G36="",G36=""),"",$D$3&"_"&ROW()-13-COUNTBLANK($G$14:G36)) | B36: Chức năng ảnh hưởng
A37: =IF(AND(G37="",G37=""),"",$D$3&"_"&ROW()-13-COUNTBLANK($G$14:G37)) | B37: N/A | N37: =IF(OR(IF(M37="",IF(L37="",IF(K37="","",K37), L37),M37)="F")=TRUE,"F", IF(OR( IF(M37="",IF(L37="",IF(K37="","",K37), L37),M37)="PE")=TRUE,"PE", IF(AND(IF(M37="",IF(L37="",IF(K37="","",K37), L37),M37)="")=TRUE,"","P")))
A38: =IF(AND(G38="",G38=""),"",$D$3&"_"&ROW()-13-COUNTBLANK($G$14:G38)) | B38: An toàn thông tin (Các trường hợp kiểm thử đảm bảo an toàn thông tin theo hướng dẫn kiểm thử an toàn thông tin)
A39: =IF(AND(G39="",G39=""),"",$D$3&"_"&ROW()-13-COUNTBLANK($G$14:G39)) | B39: N/A | N39: =IF(OR(IF(M39="",IF(L39="",IF(K39="","",K39), L39),M39)="F")=TRUE,"F", IF(OR( IF(M39="",IF(L39="",IF(K39="","",K39), L39),M39)="PE")=TRUE,"PE", IF(AND(IF(M39="",IF(L39="",IF(K39="","",K39), L39),M39)="")=TRUE,"","P")))

Sheet Convention
A1: CONVENTION
A2: STT | B2: MÔ TẢ
A3: 1 | B3: ID
B4: Đây là trường bắt buộc, thể hiện số thứ tự các test case.
B5: ID được đánh theo format Mã chức năng kiểm thử_Số thứ tự
B6: Số thứ tự tăng dần, theo công thức có sẵn
A7: 2 | B7: Mục đích kiểm thử
B8: Bắt buộc test case mở đầu bằng 1 trong các từ : Kiểm tra hoặc Verify. Ví dụ: Kiểm tra khi gửi bản tin trừ tiền sang ngân hàng….
A9: 3 | B9: Trường hợp kiểm thử
B10: Mô tả ngắn gọn, chính xác trường hợp cần kiểm tra tương ứng mục đích kiểm thử. Ví dụ, với mục đích kiểm thử ở mục 2 có các trường hợp: Số dư không đủ hoặc Số tài khoản thụ hưởng không tồn tại, …
B11: Tuỳ theo cách phân rã, trường hợp kiểm thử có thể là mục đích kiểm thử
A12: 4 | B12: Data test
B13: Mô tả các bước chuẩn bị dữ liệu đầu vào cho case tương ứng
A14: 5 | B14: Các bước thực hiện
B15: - Mô tả chi tiết từng bước một cho đến khi ra được kết quả mong muốn
B16: - Các case có nhiều bước thì bắt buộc đánh số thứ tự thực hiện .Eg: Step 1, Step 2,....
A17: 6 | B17: Kết quả mong muốn
B18: - Mô tả kết quả mong muốn đúng với mục đích kiểm tra, đúng với yêu cầu khách hàng - Một test case có thể có nhiều expected result. Mỗi expected result tách ra 1 hàng
A19: 7 | B19: Tên trình duyệt
B20: Với các trình duyệt thực hiện kiểm thử, yêu cầu điền chính xác trình duyệt và version thực hiện kiểm thử trên thực tế. Ví dụ Firefox 42 /Chrome/Android 8 /IOS 13….
A21: 8 | B21: Kết quả test
B22: P | C22: Khi thực tế đúng với kết quả mong muốn
B23: F | C23: Khi thực tế không đúng kết quả mong muốn
B24: PE | C24: Khi không thể tạo được môi trường test hoặc trường hợp không thể xảy ra trên thực tế hoặc case không nằm trong phạm vi test của lần nâng cấp sửa đổi.
A25: 9 | B25: Mã lỗi
B26: Với các case có kết quả là F, yêu cầu cần điền mã lỗi là link tới ID lỗi được log trên Jira
A27: 10 | B27: Ghi chú
B28: Với các case có kết quả là PE, ghi rõ lí do ở cột Ghi chú Hoặc chú thích cho các trường hợp kết quả test là F nhưng không fix trong giai đoạn này
A29: 11 | B29: Cách đặt tên file
B30: Đặt theo đúng format KBKTCN_Tên dự án_Tên phân hệ/Tên chức năng_version (trong đó version được đánh theo quy tắc tăng dần v1.0, v1.1)
A31: 12 | B31: Cách đặt tên sheet
B32: Mỗi sheet được định nghĩa là 1 chức năng tương ứng với 1 màn hình Đặt tên ngắn gọn, dễ hiểu có thể viết tắt nếu tên chức năng quá dài Tuy nhiên khi đặt tên chú ý tên là tiếng việt không dấu và viết liền nhau với quy tắc với chữ cái đầu tiên sẽ viết hoa Ví dụ màn hình chức năng Chuyển khoản theo SĐT sẽ đặt tên là ChuyenKhoanTheoSDT
A33: 13 | B33: Quy định bố cục trong mỗi sheet
B34: Trong mỗi sheet, sẽ bao gồm n chức năng nhỏ trên màn hình. Mỗi chức năng sẽ bao gồm 3 phần: Giao diện, Chức năng và An toàn thông tin.
B35: Đối với 1 chức năng lớn, phần "Giao diện", "Chức năng", "An toàn thông tin" nếu không có phần nào, thì để N/A phần đó Ví dụ: chức năng A không có UI/UX, khi viết testcase, phần Giao diện sẽ để N/A
B36: Được phép Hide các cột ứng với các trình duyệt mà không thực hiện kiểm thử (không được phép xóa vì sẽ ảnh hưởng đến công thức tính pass fail)

Sheet API_lay_DS_JD_da_dong_bo
C1: KỊCH BẢN KIỂM THỬ *
C2: Tên màn hình/Tên chức năng | D2: API lấy danh sách JD đã đồng bộ
C3: Mã testcase | D3: JD
C4: Số testcase đạt (P) | D4: =COUNTIF($N$13:$N$999,"P") -> 0
C5: Số testcase không đạt (F) | D5: =COUNTIF($N$13:$N$999,"F") -> 0
C6: Số testcase đang xem xét (PE) | D6: =COUNTIF($N$13:$N$999,"PE") -> 0
C7: Số testcase chưa test | D7: =D8-D4-D5-D6 -> 85
C8: Tổng số testcase | D8: =COUNTA($G$13:$G$999) -> 85
A10: ID | B10: Mục đích kiểm thử | C10: Trường hợp kiểm thử | D10: Data test | E10: cURL | F10: Các bước thực hiện | G10: Kết quả mong muốn | H10: Thứ tự ưu tiên | I10: Mức độ nghiêm trọng | J10: Hình ảnh | K10: Manual test | L10: Manual test | M10: Manual test | N10: Kết quả test (M) | O10: Mã lỗi | P10: Ghi chú
A11: ID | B11: Mục đích kiểm thử | C11: Trường hợp kiểm thử | D11: Data test | E11: cURL | F11: Các bước thực hiện | G11: Kết quả mong muốn | H11: Thứ tự ưu tiên | I11: Mức độ nghiêm trọng | J11: Hình ảnh | K11: Postman | L11: Postman | M11: Postman | N11: Kết quả test (M) | O11: Mã lỗi | P11: Ghi chú
A12: ID | B12: Mục đích kiểm thử | C12: Trường hợp kiểm thử | D12: Data test | E12: cURL | F12: Các bước thực hiện | G12: Kết quả mong muốn | H12: Thứ tự ưu tiên | I12: Mức độ nghiêm trọng | J12: Hình ảnh | K12: Lần 1 | L12: Lần 2 | M12: Lần 3 | N12: Kết quả test (M) | O12: Mã lỗi | P12: Ghi chú
B13: Chức năng: API lấy danh sách JD đã đồng bộ Method: GET MT alpha: Url: http://192.168.1.131:3002/api/job-descriptions Authorization: Bearer <validHrAccessToken> Query params: page, limit, search, sourceSystem, status, latestSyncedOnly, sortBy, sortOrder Request body: N/A
A14: =IF(AND(G14="",G14=""),"",$D$3&"_"&ROW()-13-COUNTBLANK($G$14:G14)) | B14: Kiểm tra validate request
A15: =IF(AND(G15="",G15=""),"",$D$3&"_"&ROW()-13-COUNTBLANK($G$14:G15)) | B15: Kiểm tra validity của method
A16: =IF(AND(G16="",G16=""),"",$D$3&"_"&ROW()-13-COUNTBLANK($G$14:G16)) -> JD_1 | B16: Kiểm tra validity của method | C16: Kiểm tra truyền đúng method của API (method = GET) | D16: Authorization: Bearer <validHrAccessToken> Method: GET URL: http://192.168.1.131:3002/api/job-descriptions Query params: N/A Request body: N/A | E16: curl -X GET "http://192.168.1.131:3002/api/job-descriptions" ^ -H "Authorization: Bearer <validHrAccessToken>" | F16: 1. Chuẩn bị accessToken theo Data test. 2. Gửi request GET /api/job-descriptions với header và query parameter như Data test. 3. Kiểm tra status code và response body. | G16: 1. Kết quả trả về: - Status code: 200 OK - API thực thi thành công và trả về response như format chung | H16: HIGH | I16: MAJOR | N16: =IF(OR(IF(M16="",IF(L16="",IF(K16="","",K16),L16),M16)="F")=TRUE,"F",IF(OR(IF(M16="",IF(L16="",IF(K16="","",K16),L16),M16)="PE")=TRUE,"PE",IF(AND(IF(M16="",IF(L16="",IF(K16="","",K16),L16),M16)="")=TRUE,"","P")))
A17: =IF(AND(G17="",G17=""),"",$D$3&"_"&ROW()-13-COUNTBLANK($G$14:G17)) -> JD_2 | C17: Kiểm tra truyền sai method của API | D17: Authorization: Bearer <validHrAccessToken> Method: POST URL: http://192.168.1.131:3002/api/job-descriptions Query params: N/A Request body: N/A | E17: curl -X POST "http://192.168.1.131:3002/api/job-descriptions" ^ -H "Authorization: Bearer <validHrAccessToken>" | F17: 1. Chuẩn bị accessToken theo Data test. 2. Gửi request GET /api/job-descriptions với header và query parameter như Data test. 3. Kiểm tra status code và response body. | G17: 1. Kết quả trả về: - Status code: 404 Not Found | H17: MEDIUM | I17: MAJOR | N17: =IF(OR(IF(M17="",IF(L17="",IF(K17="","",K17),L17),M17)="F")=TRUE,"F",IF(OR(IF(M17="",IF(L17="",IF(K17="","",K17),L17),M17)="PE")=TRUE,"PE",IF(AND(IF(M17="",IF(L17="",IF(K17="","",K17),L17),M17)="")=TRUE,"","P")))
A18: =IF(AND(G18="",G18=""),"",$D$3&"_"&ROW()-13-COUNTBLANK($G$14:G18)) | B18: Kiểm tra validity của URL Request
A19: =IF(AND(G19="",G19=""),"",$D$3&"_"&ROW()-13-COUNTBLANK($G$14:G19)) -> JD_3 | B19: Kiểm tra validity của URL Request | C19: Kiểm tra truyền đúng URL Request của API | D19: Authorization: Bearer <validHrAccessToken> Method: GET URL: http://192.168.1.131:3002/api/job-descriptions Query params: N/A Request body: N/A | E19: curl -X GET "http://192.168.1.131:3002/api/job-descriptions" ^ -H "Authorization: Bearer <validHrAccessToken>" | F19: 1. Chuẩn bị accessToken theo Data test. 2. Gửi request GET /api/job-descriptions với header và query parameter như Data test. 3. Kiểm tra status code và response body. | G19: 1. Kết quả trả về: - Status code: 200 OK - API thực thi thành công và trả về response như format chung | H19: HIGH | I19: MAJOR | N19: =IF(OR(IF(M19="",IF(L19="",IF(K19="","",K19),L19),M19)="F")=TRUE,"F",IF(OR(IF(M19="",IF(L19="",IF(K19="","",K19),L19),M19)="PE")=TRUE,"PE",IF(AND(IF(M19="",IF(L19="",IF(K19="","",K19),L19),M19)="")=TRUE,"","P")))
A20: =IF(AND(G20="",G20=""),"",$D$3&"_"&ROW()-13-COUNTBLANK($G$14:G20)) -> JD_4 | C20: Kiểm tra truyền sai URL Request của API | D20: Authorization: Bearer <validHrAccessToken> Method: GET URL: http://192.168.1.131:3002/api/job-descriptions/invalid Query params: N/A Request body: N/A | E20: curl -X GET "http://192.168.1.131:3002/api/job-descriptions/invalid" ^ -H "Authorization: Bearer <validHrAccessToken>" | F20: 1. Chuẩn bị accessToken theo Data test. 2. Gửi request GET /api/job-descriptions với header và query parameter như Data test. 3. Kiểm tra status code và response body. | G20: 1. Kết quả trả về: - Status code: 404 Not Found | H20: MEDIUM | I20: MAJOR | N20: =IF(OR(IF(M20="",IF(L20="",IF(K20="","",K20),L20),M20)="F")=TRUE,"F",IF(OR(IF(M20="",IF(L20="",IF(K20="","",K20),L20),M20)="PE")=TRUE,"PE",IF(AND(IF(M20="",IF(L20="",IF(K20="","",K20),L20),M20)="")=TRUE,"","P")))
A21: =IF(AND(G21="",G21=""),"",$D$3&"_"&ROW()-13-COUNTBLANK($G$14:G21)) | B21: Kiểm tra validate query parameter
A22: =IF(AND(G22="",G22=""),"",$D$3&"_"&ROW()-13-COUNTBLANK($G$14:G22)) | B22: Kiểm tra trường page
A23: =IF(AND(G23="",G23=""),"",$D$3&"_"&ROW()-13-COUNTBLANK($G$14:G23)) -> JD_5 | B23: Kiểm tra trường page | C23: Kiểm tra không truyền page | D23: Authorization: Bearer <validHrAccessToken> Method: GET URL: http://192.168.1.131:3002/api/job-descriptions Query params: N/A Request body: N/A | E23: curl -X GET "http://192.168.1.131:3002/api/job-descriptions" ^ -H "Authorization: Bearer <validHrAccessToken>" | F23: 1. Chuẩn bị accessToken theo Data test. 2. Gửi request GET /api/job-descriptions với header và query parameter như Data test. 3. Kiểm tra status code và response body. | G23: 1. Kết quả trả về: - Status code: 200 OK - API thực thi thành công và trả về response như format chung | H23: HIGH | I23: MAJOR | N23: =IF(OR(IF(M23="",IF(L23="",IF(K23="","",K23),L23),M23)="F")=TRUE,"F",IF(OR(IF(M23="",IF(L23="",IF(K23="","",K23),L23),M23)="PE")=TRUE,"PE",IF(AND(IF(M23="",IF(L23="",IF(K23="","",K23),L23),M23)="")=TRUE,"","P")))
A24: =IF(AND(G24="",G24=""),"",$D$3&"_"&ROW()-13-COUNTBLANK($G$14:G24)) -> JD_6 | C24: Kiểm tra truyền page = null/rỗng | D24: Authorization: Bearer <validHrAccessToken> Method: GET URL: http://192.168.1.131:3002/api/job-descriptions Query params: page= Request body: N/A | E24: curl -X GET "http://192.168.1.131:3002/api/job-descriptions?page=" ^ -H "Authorization: Bearer <validHrAccessToken>" | F24: 1. Chuẩn bị accessToken theo Data test. 2. Gửi request GET /api/job-descriptions với header và query parameter như Data test. 3. Kiểm tra status code và response body. | G24: 1. Kết quả trả về: - Status code: 200 OK - API thực thi thành công và trả về response như format chung | H24: HIGH | I24: MAJOR | N24: =IF(OR(IF(M24="",IF(L24="",IF(K24="","",K24),L24),M24)="F")=TRUE,"F",IF(OR(IF(M24="",IF(L24="",IF(K24="","",K24),L24),M24)="PE")=TRUE,"PE",IF(AND(IF(M24="",IF(L24="",IF(K24="","",K24),L24),M24)="")=TRUE,"","P")))
A25: =IF(AND(G25="",G25=""),"",$D$3&"_"&ROW()-13-COUNTBLANK($G$14:G25)) -> JD_7 | C25: Kiểm tra truyền page > 0 | D25: Authorization: Bearer <validHrAccessToken> Method: GET URL: http://192.168.1.131:3002/api/job-descriptions Query params: page=1 Request body: N/A | E25: curl -X GET "http://192.168.1.131:3002/api/job-descriptions?page=1" ^ -H "Authorization: Bearer <validHrAccessToken>" | F25: 1. Chuẩn bị accessToken theo Data test. 2. Gửi request GET /api/job-descriptions với header và query parameter như Data test. 3. Kiểm tra status code và response body. | G25: 1. Kết quả trả về: - Status code: 200 OK - API thực thi thành công và trả về response như format chung - MM: response trả về trang dữ liệu tương ứng với page đã truyền | H25: HIGH | I25: MAJOR | N25: =IF(OR(IF(M25="",IF(L25="",IF(K25="","",K25),L25),M25)="F")=TRUE,"F",IF(OR(IF(M25="",IF(L25="",IF(K25="","",K25),L25),M25)="PE")=TRUE,"PE",IF(AND(IF(M25="",IF(L25="",IF(K25="","",K25),L25),M25)="")=TRUE,"","P")))
A26: =IF(AND(G26="",G26=""),"",$D$3&"_"&ROW()-13-COUNTBLANK($G$14:G26)) -> JD_8 | C26: Kiểm tra truyền page = chuỗi space | D26: Authorization: Bearer <validHrAccessToken> Method: GET URL: http://192.168.1.131:3002/api/job-descriptions Query params: page= Request body: N/A | E26: curl -X GET "http://192.168.1.131:3002/api/job-descriptions?page=%20" ^ -H "Authorization: Bearer <validHrAccessToken>" | F26: 1. Chuẩn bị accessToken theo Data test. 2. Gửi request GET /api/job-descriptions với header và query parameter như Data test. 3. Kiểm tra status code và response body. | G26: 1. Kết quả trả về: - Status code: 400 Bad Request - Message: Request payload is invalid | H26: MEDIUM | I26: MAJOR | N26: =IF(OR(IF(M26="",IF(L26="",IF(K26="","",K26),L26),M26)="F")=TRUE,"F",IF(OR(IF(M26="",IF(L26="",IF(K26="","",K26),L26),M26)="PE")=TRUE,"PE",IF(AND(IF(M26="",IF(L26="",IF(K26="","",K26),L26),M26)="")=TRUE,"","P")))
A27: =IF(AND(G27="",G27=""),"",$D$3&"_"&ROW()-13-COUNTBLANK($G$14:G27)) -> JD_9 | C27: Kiểm tra truyền page = 0 | D27: Authorization: Bearer <validHrAccessToken> Method: GET URL: http://192.168.1.131:3002/api/job-descriptions Query params: page=0 Request body: N/A | E27: curl -X GET "http://192.168.1.131:3002/api/job-descriptions?page=0" ^ -H "Authorization: Bearer <validHrAccessToken>" | F27: 1. Chuẩn bị accessToken theo Data test. 2. Gửi request GET /api/job-descriptions với header và query parameter như Data test. 3. Kiểm tra status code và response body. | G27: 1. Kết quả trả về: - Status code: 400 Bad Request - Message: Request payload is invalid | H27: MEDIUM | I27: MAJOR | N27: =IF(OR(IF(M27="",IF(L27="",IF(K27="","",K27),L27),M27)="F")=TRUE,"F",IF(OR(IF(M27="",IF(L27="",IF(K27="","",K27),L27),M27)="PE")=TRUE,"PE",IF(AND(IF(M27="",IF(L27="",IF(K27="","",K27),L27),M27)="")=TRUE,"","P")))
A28: =IF(AND(G28="",G28=""),"",$D$3&"_"&ROW()-13-COUNTBLANK($G$14:G28)) -> JD_10 | C28: Kiểm tra truyền page = < 0 | D28: Authorization: Bearer <validHrAccessToken> Method: GET URL: http://192.168.1.131:3002/api/job-descriptions Query params: page=-1 Request body: N/A | E28: curl -X GET "http://192.168.1.131:3002/api/job-descriptions?page=-1" ^ -H "Authorization: Bearer <validHrAccessToken>" | F28: 1. Chuẩn bị accessToken theo Data test. 2. Gửi request GET /api/job-descriptions với header và query parameter như Data test. 3. Kiểm tra status code và response body. | G28: 1. Kết quả trả về: - Status code: 400 Bad Request - Message: Request payload is invalid | H28: MEDIUM | I28: MAJOR | N28: =IF(OR(IF(M28="",IF(L28="",IF(K28="","",K28),L28),M28)="F")=TRUE,"F",IF(OR(IF(M28="",IF(L28="",IF(K28="","",K28),L28),M28)="PE")=TRUE,"PE",IF(AND(IF(M28="",IF(L28="",IF(K28="","",K28),L28),M28)="")=TRUE,"","P")))
A29: =IF(AND(G29="",G29=""),"",$D$3&"_"&ROW()-13-COUNTBLANK($G$14:G29)) -> JD_11 | C29: Kiểm tra truyền page = số thực | D29: Authorization: Bearer <validHrAccessToken> Method: GET URL: http://192.168.1.131:3002/api/job-descriptions Query params: page=1.5 Request body: N/A | E29: curl -X GET "http://192.168.1.131:3002/api/job-descriptions?page=1.5" ^ -H "Authorization: Bearer <validHrAccessToken>" | F29: 1. Chuẩn bị accessToken theo Data test. 2. Gửi request GET /api/job-descriptions với header và query parameter như Data test. 3. Kiểm tra status code và response body. | G29: 1. Kết quả trả về: - Status code: 400 Bad Request - Message: Request payload is invalid | H29: MEDIUM | I29: MAJOR | N29: =IF(OR(IF(M29="",IF(L29="",IF(K29="","",K29),L29),M29)="F")=TRUE,"F",IF(OR(IF(M29="",IF(L29="",IF(K29="","",K29),L29),M29)="PE")=TRUE,"PE",IF(AND(IF(M29="",IF(L29="",IF(K29="","",K29),L29),M29)="")=TRUE,"","P")))
A30: =IF(AND(G30="",G30=""),"",$D$3&"_"&ROW()-13-COUNTBLANK($G$14:G30)) -> JD_12 | C30: Kiểm tra truyền page = chữ | D30: Authorization: Bearer <validHrAccessToken> Method: GET URL: http://192.168.1.131:3002/api/job-descriptions Query params: page=abc Request body: N/A | E30: curl -X GET "http://192.168.1.131:3002/api/job-descriptions?page=abc" ^ -H "Authorization: Bearer <validHrAccessToken>" | F30: 1. Chuẩn bị accessToken theo Data test. 2. Gửi request GET /api/job-descriptions với header và query parameter như Data test. 3. Kiểm tra status code và response body. | G30: 1. Kết quả trả về: - Status code: 400 Bad Request - Message: Request payload is invalid | H30: MEDIUM | I30: MAJOR | N30: =IF(OR(IF(M30="",IF(L30="",IF(K30="","",K30),L30),M30)="F")=TRUE,"F",IF(OR(IF(M30="",IF(L30="",IF(K30="","",K30),L30),M30)="PE")=TRUE,"PE",IF(AND(IF(M30="",IF(L30="",IF(K30="","",K30),L30),M30)="")=TRUE,"","P")))
A31: =IF(AND(G31="",G31=""),"",$D$3&"_"&ROW()-13-COUNTBLANK($G$14:G31)) -> JD_13 | C31: Kiểm tra truyền page = ký tự đặc biệt | D31: Authorization: Bearer <validHrAccessToken> Method: GET URL: http://192.168.1.131:3002/api/job-descriptions Query params: page=@#$ Request body: N/A | E31: curl -X GET "http://192.168.1.131:3002/api/job-descriptions?page=%40%23%24" ^ -H "Authorization: Bearer <validHrAccessToken>" | F31: 1. Chuẩn bị accessToken theo Data test. 2. Gửi request GET /api/job-descriptions với header và query parameter như Data test. 3. Kiểm tra status code và response body. | G31: 1. Kết quả trả về: - Status code: 400 Bad Request - Message: Request payload is invalid | H31: MEDIUM | I31: MAJOR | N31: =IF(OR(IF(M31="",IF(L31="",IF(K31="","",K31),L31),M31)="F")=TRUE,"F",IF(OR(IF(M31="",IF(L31="",IF(K31="","",K31),L31),M31)="PE")=TRUE,"PE",IF(AND(IF(M31="",IF(L31="",IF(K31="","",K31),L31),M31)="")=TRUE,"","P")))
A32: =IF(AND(G32="",G32=""),"",$D$3&"_"&ROW()-13-COUNTBLANK($G$14:G32)) -> JD_14 | C32: Kiểm tra truyền page = khác kiểu dữ liệu Int | D32: Authorization: Bearer <validHrAccessToken> Method: GET URL: http://192.168.1.131:3002/api/job-descriptions Query params: page[]=1 Request body: N/A | E32: curl -X GET "http://192.168.1.131:3002/api/job-descriptions?page%5B%5D=1" ^ -H "Authorization: Bearer <validHrAccessToken>" | F32: 1. Chuẩn bị accessToken theo Data test. 2. Gửi request GET /api/job-descriptions với header và query parameter như Data test. 3. Kiểm tra status code và response body. | G32: 1. Kết quả trả về: - Status code: 400 Bad Request - Message: Request payload is invalid | H32: MEDIUM | I32: MAJOR | N32: =IF(OR(IF(M32="",IF(L32="",IF(K32="","",K32),L32),M32)="F")=TRUE,"F",IF(OR(IF(M32="",IF(L32="",IF(K32="","",K32),L32),M32)="PE")=TRUE,"PE",IF(AND(IF(M32="",IF(L32="",IF(K32="","",K32),L32),M32)="")=TRUE,"","P")))
A33: =IF(AND(G33="",G33=""),"",$D$3&"_"&ROW()-13-COUNTBLANK($G$14:G33)) | B33: Kiểm tra trường limit
A34: =IF(AND(G34="",G34=""),"",$D$3&"_"&ROW()-13-COUNTBLANK($G$14:G34)) -> JD_15 | B34: Kiểm tra trường limit | C34: Kiểm tra không truyền limit | D34: Authorization: Bearer <validHrAccessToken> Method: GET URL: http://192.168.1.131:3002/api/job-descriptions Query params: N/A Request body: N/A | E34: curl -X GET "http://192.168.1.131:3002/api/job-descriptions" ^ -H "Authorization: Bearer <validHrAccessToken>" | F34: 1. Chuẩn bị accessToken theo Data test. 2. Gửi request GET /api/job-descriptions với header và query parameter như Data test. 3. Kiểm tra status code và response body. | G34: 1. Kết quả trả về: - Status code: 200 OK - API thực thi thành công và trả về response như format chung | H34: HIGH | I34: MAJOR | N34: =IF(OR(IF(M34="",IF(L34="",IF(K34="","",K34),L34),M34)="F")=TRUE,"F",IF(OR(IF(M34="",IF(L34="",IF(K34="","",K34),L34),M34)="PE")=TRUE,"PE",IF(AND(IF(M34="",IF(L34="",IF(K34="","",K34),L34),M34)="")=TRUE,"","P")))
